<?xml version="1.0" ?>
<robot name="stella" xmlns:xacro="http://ros.org/wiki/xacro">

  <xacro:include filename="$(find stella_description)/urdf/stella_slam.gazebo.xacro" />

  <!-- Init colour -->
  <xacro:property name="black" value="0.0 0.0 0.0 1.0"/>
  <xacro:property name="dark" value="0.3 0.3 0.3 1.0"/>
  <xacro:property name="light_black" value="0.4 0.4 0.4 1.0"/>
  <xacro:property name="blue" value="0.2 0.2 0.8 1.0"/>
  <xacro:property name="green" value="0.0 0.8 0.0 1.0"/>
  <xacro:property name="grey" value="0.5 0.5 0.5 1.0"/>
  <xacro:property name="orange" value="1.0 0.4235 0.0392 1.0"/>
  <xacro:property name="brown" value="0.8706 0.8118 0.7647 1.0"/>
  <xacro:property name="red" value="0.8 0.0 0.0 1.0"/>
  <xacro:property name="white" value="1.0 1.0 1.0 1.0"/>

  <!-- Define materials -->
  <xacro:macro name="material" params="name rgba">
    <material name="${name}">
      <color rgba="${rgba}"/>
    </material>
  </xacro:macro>

  <xacro:material name="black" rgba="${black}"/>
  <xacro:material name="dark" rgba="${dark}"/>
  <xacro:material name="light_black" rgba="${light_black}"/>
  <xacro:material name="blue" rgba="${blue}"/>
  <xacro:material name="green" rgba="${green}"/>
  <xacro:material name="grey" rgba="${grey}"/>
  <xacro:material name="orange" rgba="${orange}"/>
  <xacro:material name="brown" rgba="${brown}"/>
  <xacro:material name="red" rgba="${red}"/>
  <xacro:material name="white" rgba="${white}"/>

  <link name="base_footprint"/>

  <joint name="base_joint" type="fixed">
    <parent link="base_footprint"/>
    <child link="base_link" />
    <origin xyz="0.0 0.0 0.0669" rpy="0.0 0.0 0.0" frame_id="base_footprint"/>
  </joint>

  <link name="base_link">
    <visual>
      <origin xyz="0.01 0.0 0.0" rpy="0.0 0.0 0.0"/>
      <geometry>
        <mesh filename="package://stella_description/meshes/bases/stella_body.stl" scale="0.001 0.001 0.001"/>
      </geometry>
      <material name="light_black"/>
    </visual>

    <collision>
      <origin xyz="0.01 0.0 0.0685" rpy="0.0 0.0 0.0"/>
      <geometry>
        <box size="0.44 0.38 0.1371"/>
      </geometry>
    </collision>
    
    <inertial>
      <origin xyz="-0.1 0.0 0.0" rpy="0.0 0.0 0.0"/>
      <mass value="5.311"/>
      <inertia ixx="0.07221587992" ixy="0.0" ixz="0.0"
               iyy="0.09399097992" iyz="0.0"
               izz="0.14959316667" />
    </inertial>
  </link>

  <joint name="imu_joint" type="fixed">
    <parent link="base_link"/>
    <child link="imu_link"/>
    <origin xyz="0.0 0.0 0.001" rpy="0.0 0.0 0.0" frame_id="base_link"/>
  </joint>

  <link name="imu_link"/>

  <joint name="scan_joint" type="fixed">
    <parent link="base_link"/>
    <child link="base_scan"/>
    <origin xyz="0.145 0.0 0.178" rpy="0.0 0.0 0.0" frame_id="base_link"/>
  </joint>

  <link name="base_scan">
    <visual>
      <origin xyz="-0.06775 -0.0355 -0.0415" rpy="0.0 0.0 0.0"/>
      <geometry>
        <mesh filename="package://stella_description/meshes/bases/ydlidar_x4.STL" scale="0.001 0.001 0.001"/>
      </geometry>
      <material name="dark"/>
    </visual>

    <collision>
      <origin xyz="-0.06775 -0.0355 -0.0415" rpy="0.0 0.0 0.0"/>
      <geometry>
        <cylinder length="0.0315" radius="0.055"/>
      </geometry>
    </collision>

    <inertial>
      <origin xyz="-0.06775 -0.0355 -0.0415" rpy="0.0 0.0 0.0"/>
      <mass value="0.189" />
      <inertia ixx="0.00015856" ixy="0.0" ixz="0.0"
               iyy="0.00015856" iyz="0.0"
               izz="0.00028586"/>
    </inertial>
  </link>

  <joint name="caster_joint" type="continuous">
    <parent link="base_link"/>
    <child link="caster_link"/>
    <origin xyz="-0.1566 0.0 0.0" rpy="0.0 0.0 0.0" frame_id="base_link"/>
    <axis xyz="0 0 1"/>
    <limit effort="10000" velocity="1000"/>
    <joint_properties damping="1.0" friction="1.0"/>
  </joint> 

  <link name="caster_link">
    <visual>
      <origin xyz="0.0 0.0 0.002" rpy="0.0 0.0 3.1416"/>
      <geometry>
        <mesh filename="package://stella_description/meshes/bases/STELLA_N1_caster.stl" scale="0.00106 0.00106 0.00106"/>
      </geometry>
      <material name="dark"/>
    </visual>

    <collision>
      <origin xyz="0.0 0.0 0.002" rpy="0.0 0.0 1.5708"/>
      <geometry>
        <mesh filename="package://stella_description/meshes/bases/STELLA_N1_caster.stl" scale="0.00106 0.00106 0.00106"/>
      </geometry>
    </collision>

    <inertial>
      <origin xyz="0.0 0.0 0.0" rpy="0.0 0.0 4.7134"/>
      <mass value="0.01" />
      <inertia ixx="3.083333e-06" ixy="0.0" ixz="0.0"
               iyy="3.083333e-06" iyz="0.0"
               izz="2.000000e-06"/>
    </inertial>
  </link>

  <joint name="caster_wheel_joint" type="continuous">
    <parent link="caster_link"/>
    <child link="caster_wheel_link"/>
    <origin xyz="-0.02385 0.0 -0.0452" rpy="1.5708 0.0 0.0" frame_id="base_link"/>
    <axis xyz="0 0 1"/>
    <limit effort="10000" velocity="1000"/>
    <joint_properties damping="1.0" friction="1.0"/>
  </joint>

  <link name="caster_wheel_link">
    <visual>
      <origin xyz="0.0 0.0 0.0" rpy="0.0 0.0 0.0"/>
      <geometry>
        <cylinder length="0.02" radius="0.0215"/>
      </geometry>
      <material name="dark"/>
    </visual>

    <collision>
      <origin xyz="0.0 0.0 0.0" rpy="0.0 0.0 0.0"/>
      <geometry>
        <cylinder length="0.02" radius="0.0215"/>
      </geometry>
    </collision>

    <inertial>
      <origin xyz="0.0 0.0 0.0" rpy="0.0 0.0 0.0"/>
      <mass value="0.01" />
      <inertia ixx="1.4889583e-06" ixy="0.0" ixz="0.0"
               iyy="1.4889583e-06" iyz="0.0"
               izz="2.3112499e-06"/>
    </inertial>
    
  </link>

  <joint name="wheel_l_joint" type="continuous">
    <parent link="base_link"/>
    <child link="wheel_l_link"/>
    <origin xyz="0.098 0.12 0.0235" rpy="-1.5708 0.0 0.0" frame_id="base_link"/>
    <axis xyz="0 0 1"/>
    <limit effort="10000" velocity="1000"/>
    <joint_properties damping="1.0" friction="1.0"/>
  </joint>

  <link name="wheel_l_link">
    <visual>
      <origin xyz="0.0 0.0 0.0" rpy="0.0 0.0 0.0"/>
      <geometry>
        <mesh filename="package://stella_description/meshes/bases/STELLA_N1_wheel.stl" scale="0.001 0.001 0.001"/>
      </geometry>
      <material name="dark"/>
    </visual>

    <collision>
      <origin xyz="0.0 0.0 0.0307" rpy="0.0 0.0 0.0"/>
      <geometry>
        <cylinder length="0.0615" radius="0.09"/>
      </geometry>
    </collision>

    <inertial>
      <origin xyz="0.0 0.0 0.0" rpy="0.0 0.0 0.0"/>
      <mass value="0.84" />
      <inertia ixx="0.00184275" ixy="0.0" ixz="0.0"
               iyy="0.00184275" iyz="0.0"
               izz="0.003402"/>
    </inertial>
  </link>

  <joint name="wheel_r_joint" type="continuous">
    <parent link="base_link"/>
    <child link="wheel_r_link"/>
    <origin xyz="0.098 -0.12 0.0235" rpy="-1.5708 0.0 0.0" frame_id="base_link"/>
    <axis xyz="0 0 1"/>
    <limit effort="10000" velocity="1000"/>
    <joint_properties damping="1.0" friction="1.0"/>
  </joint>

  <link name="wheel_r_link">
    <visual>
      <origin xyz="0.0 0.0 0.0" rpy="3.1415 0.0 0.0"/>
      <geometry>
        <mesh filename="package://stella_description/meshes/bases/STELLA_N1_wheel.stl" scale="0.001 0.001 0.001"/>
      </geometry>
      <material name="dark"/>
    </visual>

    <collision>
      <origin xyz="0.0 0.0 -0.0307" rpy="3.1415 0.0 0.0"/>
      <geometry>
        <cylinder length="0.0615" radius="0.09"/>
      </geometry>
    </collision>

    <inertial>
      <origin xyz="0.0 0.0 0.0" rpy="3.1415 0.0 0.0"/>
      <mass value="0.84" />
      <inertia ixx="0.00184275" ixy="0.0" ixz="0.0"
               iyy="0.00184275" iyz="0.0"
               izz="0.003402"/>
    </inertial>
  </link>

  <joint name="cam_joint" type="fixed">
    <parent link="base_link"/>
    <child link="cam_link"/>
    <origin xyz="0.21 0.0 0.025" rpy="0.0 0.0 0.0" frame_id="base_link"/>
  </joint>
  

  <link name="cam_link"/>

</robot>
